[2024-05-13T03:54:14.045+0000] {local_task_job_runner.py:120} INFO - ::group::Pre task execution logs
[2024-05-13T03:54:14.203+0000] {taskinstance.py:2076} INFO - Dependencies all met for dep_context=non-requeueable deps ti=<TaskInstance: dag_with_postgres_to_file_3.postgres_to_file scheduled__2024-05-11T00:00:00+00:00 [queued]>
[2024-05-13T03:54:14.258+0000] {taskinstance.py:2076} INFO - Dependencies all met for dep_context=requeueable deps ti=<TaskInstance: dag_with_postgres_to_file_3.postgres_to_file scheduled__2024-05-11T00:00:00+00:00 [queued]>
[2024-05-13T03:54:14.258+0000] {taskinstance.py:2306} INFO - Starting attempt 1 of 6
[2024-05-13T03:54:14.524+0000] {taskinstance.py:2330} INFO - Executing <Task(PythonOperator): postgres_to_file> on 2024-05-11 00:00:00+00:00
[2024-05-13T03:54:14.559+0000] {logging_mixin.py:188} WARNING - /home/***/.local/lib/python3.12/site-packages/***/task/task_runner/standard_task_runner.py:61 DeprecationWarning: This process (pid=269) is multi-threaded, use of fork() may lead to deadlocks in the child.
[2024-05-13T03:54:14.560+0000] {standard_task_runner.py:63} INFO - Started process 289 to run task
[2024-05-13T03:54:14.571+0000] {standard_task_runner.py:90} INFO - Running: ['***', 'tasks', 'run', 'dag_with_postgres_to_file_3', 'postgres_to_file', 'scheduled__2024-05-11T00:00:00+00:00', '--job-id', '150', '--raw', '--subdir', 'DAGS_FOLDER/postgres_to_csv.py', '--cfg-path', '/tmp/tmppz5p5xgg']
[2024-05-13T03:54:14.605+0000] {standard_task_runner.py:91} INFO - Job 150: Subtask postgres_to_file
[2024-05-13T03:54:14.874+0000] {task_command.py:426} INFO - Running <TaskInstance: dag_with_postgres_to_file_3.postgres_to_file scheduled__2024-05-11T00:00:00+00:00 [running]> on host dab92a57e2e4
[2024-05-13T03:54:15.276+0000] {taskinstance.py:2648} INFO - Exporting env vars: AIRFLOW_CTX_DAG_OWNER='myself' AIRFLOW_CTX_DAG_ID='dag_with_postgres_to_file_3' AIRFLOW_CTX_TASK_ID='postgres_to_file' AIRFLOW_CTX_EXECUTION_DATE='2024-05-11T00:00:00+00:00' AIRFLOW_CTX_TRY_NUMBER='1' AIRFLOW_CTX_DAG_RUN_ID='scheduled__2024-05-11T00:00:00+00:00'
[2024-05-13T03:54:15.277+0000] {taskinstance.py:430} INFO - ::endgroup::
[2024-05-13T03:54:15.340+0000] {base.py:84} INFO - Using connection ID 'postgres_localhost' for task execution.
[2024-05-13T03:54:15.345+0000] {taskinstance.py:441} INFO - ::group::Post task execution logs
[2024-05-13T03:54:15.346+0000] {taskinstance.py:2905} ERROR - Task failed with exception
Traceback (most recent call last):
  File "/home/airflow/.local/lib/python3.12/site-packages/airflow/models/taskinstance.py", line 465, in _execute_task
    result = _execute_callable(context=context, **execute_callable_kwargs)
             ^^^^^^^^^^^^^^^^^^^^^^^^^^^^^^^^^^^^^^^^^^^^^^^^^^^^^^^^^^^^^
  File "/home/airflow/.local/lib/python3.12/site-packages/airflow/models/taskinstance.py", line 432, in _execute_callable
    return execute_callable(context=context, **execute_callable_kwargs)
           ^^^^^^^^^^^^^^^^^^^^^^^^^^^^^^^^^^^^^^^^^^^^^^^^^^^^^^^^^^^^
  File "/home/airflow/.local/lib/python3.12/site-packages/airflow/models/baseoperator.py", line 400, in wrapper
    return func(self, *args, **kwargs)
           ^^^^^^^^^^^^^^^^^^^^^^^^^^^
  File "/home/airflow/.local/lib/python3.12/site-packages/airflow/operators/python.py", line 235, in execute
    return_value = self.execute_callable()
                   ^^^^^^^^^^^^^^^^^^^^^^^
  File "/home/airflow/.local/lib/python3.12/site-packages/airflow/operators/python.py", line 252, in execute_callable
    return self.python_callable(*self.op_args, **self.op_kwargs)
           ^^^^^^^^^^^^^^^^^^^^^^^^^^^^^^^^^^^^^^^^^^^^^^^^^^^^^
  File "/opt/airflow/dags/postgres_to_csv.py", line 19, in postgres_to_file
    conn = hook.get_conn()
           ^^^^^^^^^^^^^^^
  File "/home/airflow/.local/lib/python3.12/site-packages/airflow/providers/postgres/hooks/postgres.py", line 161, in get_conn
    self.conn = psycopg2.connect(**conn_args)
                ^^^^^^^^^^^^^^^^^^^^^^^^^^^^^
  File "/home/airflow/.local/lib/python3.12/site-packages/psycopg2/__init__.py", line 122, in connect
    conn = _connect(dsn, connection_factory=connection_factory, **kwasync)
           ^^^^^^^^^^^^^^^^^^^^^^^^^^^^^^^^^^^^^^^^^^^^^^^^^^^^^^^^^^^^^^^
psycopg2.OperationalError: connection to server at "172.23.0.2", port 5432 failed: Connection refused
	Is the server running on that host and accepting TCP/IP connections?

[2024-05-13T03:54:15.373+0000] {taskinstance.py:1206} INFO - Marking task as UP_FOR_RETRY. dag_id=dag_with_postgres_to_file_3, task_id=postgres_to_file, run_id=scheduled__2024-05-11T00:00:00+00:00, execution_date=20240511T000000, start_date=20240513T035414, end_date=20240513T035415
[2024-05-13T03:54:15.394+0000] {standard_task_runner.py:110} ERROR - Failed to execute job 150 for task postgres_to_file (connection to server at "172.23.0.2", port 5432 failed: Connection refused
	Is the server running on that host and accepting TCP/IP connections?
; 289)
[2024-05-13T03:54:15.460+0000] {local_task_job_runner.py:240} INFO - Task exited with return code 1
[2024-05-13T03:54:15.530+0000] {taskinstance.py:3498} INFO - 0 downstream tasks scheduled from follow-on schedule check
[2024-05-13T03:54:15.533+0000] {local_task_job_runner.py:222} INFO - ::endgroup::
[2024-05-13T04:02:29.477+0000] {local_task_job_runner.py:120} INFO - ::group::Pre task execution logs
[2024-05-13T04:02:29.524+0000] {taskinstance.py:2076} INFO - Dependencies all met for dep_context=non-requeueable deps ti=<TaskInstance: dag_with_postgres_to_file_3.postgres_to_file scheduled__2024-05-11T00:00:00+00:00 [queued]>
[2024-05-13T04:02:29.536+0000] {taskinstance.py:2076} INFO - Dependencies all met for dep_context=requeueable deps ti=<TaskInstance: dag_with_postgres_to_file_3.postgres_to_file scheduled__2024-05-11T00:00:00+00:00 [queued]>
[2024-05-13T04:02:29.537+0000] {taskinstance.py:2306} INFO - Starting attempt 1 of 6
[2024-05-13T04:02:29.560+0000] {taskinstance.py:2330} INFO - Executing <Task(PythonOperator): postgres_to_file> on 2024-05-11 00:00:00+00:00
[2024-05-13T04:02:29.570+0000] {standard_task_runner.py:90} INFO - Running: ['***', 'tasks', 'run', 'dag_with_postgres_to_file_3', 'postgres_to_file', 'scheduled__2024-05-11T00:00:00+00:00', '--job-id', '176', '--raw', '--subdir', 'DAGS_FOLDER/postgres_to_csv.py', '--cfg-path', '/tmp/tmpcipfhqgc']
[2024-05-13T04:02:29.572+0000] {standard_task_runner.py:91} INFO - Job 176: Subtask postgres_to_file
[2024-05-13T04:02:29.577+0000] {logging_mixin.py:188} WARNING - /home/***/.local/lib/python3.12/site-packages/***/task/task_runner/standard_task_runner.py:61 DeprecationWarning: This process (pid=419) is multi-threaded, use of fork() may lead to deadlocks in the child.
[2024-05-13T04:02:29.577+0000] {standard_task_runner.py:63} INFO - Started process 422 to run task
[2024-05-13T04:02:29.635+0000] {task_command.py:426} INFO - Running <TaskInstance: dag_with_postgres_to_file_3.postgres_to_file scheduled__2024-05-11T00:00:00+00:00 [running]> on host dab92a57e2e4
[2024-05-13T04:02:29.764+0000] {taskinstance.py:2648} INFO - Exporting env vars: AIRFLOW_CTX_DAG_OWNER='myself' AIRFLOW_CTX_DAG_ID='dag_with_postgres_to_file_3' AIRFLOW_CTX_TASK_ID='postgres_to_file' AIRFLOW_CTX_EXECUTION_DATE='2024-05-11T00:00:00+00:00' AIRFLOW_CTX_TRY_NUMBER='1' AIRFLOW_CTX_DAG_RUN_ID='scheduled__2024-05-11T00:00:00+00:00'
[2024-05-13T04:02:29.765+0000] {taskinstance.py:430} INFO - ::endgroup::
[2024-05-13T04:02:29.801+0000] {base.py:84} INFO - Using connection ID 'postgres_localhost' for task execution.
[2024-05-13T04:02:29.814+0000] {postgres_to_csv.py:27} INFO - Saved orders data in text file
[2024-05-13T04:02:29.815+0000] {python.py:237} INFO - Done. Returned value was: None
[2024-05-13T04:02:29.816+0000] {taskinstance.py:441} INFO - ::group::Post task execution logs
[2024-05-13T04:02:29.830+0000] {taskinstance.py:1206} INFO - Marking task as SUCCESS. dag_id=dag_with_postgres_to_file_3, task_id=postgres_to_file, run_id=scheduled__2024-05-11T00:00:00+00:00, execution_date=20240511T000000, start_date=20240513T040229, end_date=20240513T040229
[2024-05-13T04:02:29.872+0000] {local_task_job_runner.py:240} INFO - Task exited with return code 0
[2024-05-13T04:02:29.898+0000] {taskinstance.py:3498} INFO - 0 downstream tasks scheduled from follow-on schedule check
[2024-05-13T04:02:29.900+0000] {local_task_job_runner.py:222} INFO - ::endgroup::
