[2024-05-09T06:37:04.721+0000] {task_context_logger.py:104} ERROR - Executor reports task instance <TaskInstance: python_operator_v3.Welcome scheduled__2024-05-06T00:00:00+00:00 [queued]> finished (failed) although the task says it's queued. (Info: None) Was the task killed externally?
