[2024-05-09T08:37:28.498+0000] {task_context_logger.py:104} ERROR - Executor reports task instance <TaskInstance: scheduler_crontab_v3.hello_world scheduled__2024-05-08T00:00:00+00:00 [queued]> finished (failed) although the task says it's queued. (Info: None) Was the task killed externally?
