[2024-05-13T03:54:13.623+0000] {local_task_job_runner.py:120} INFO - ::group::Pre task execution logs
[2024-05-13T03:54:13.698+0000] {taskinstance.py:2076} INFO - Dependencies all met for dep_context=non-requeueable deps ti=<TaskInstance: dag_with_postgres_to_file_3.postgres_to_file scheduled__2024-05-10T00:00:00+00:00 [queued]>
[2024-05-13T03:54:13.712+0000] {taskinstance.py:2076} INFO - Dependencies all met for dep_context=requeueable deps ti=<TaskInstance: dag_with_postgres_to_file_3.postgres_to_file scheduled__2024-05-10T00:00:00+00:00 [queued]>
[2024-05-13T03:54:13.713+0000] {taskinstance.py:2306} INFO - Starting attempt 1 of 6
[2024-05-13T03:54:13.750+0000] {taskinstance.py:2330} INFO - Executing <Task(PythonOperator): postgres_to_file> on 2024-05-10 00:00:00+00:00
[2024-05-13T03:54:13.798+0000] {logging_mixin.py:188} WARNING - /home/***/.local/lib/python3.12/site-packages/***/task/task_runner/standard_task_runner.py:61 DeprecationWarning: This process (pid=255) is multi-threaded, use of fork() may lead to deadlocks in the child.
[2024-05-13T03:54:13.800+0000] {standard_task_runner.py:63} INFO - Started process 272 to run task
[2024-05-13T03:54:13.805+0000] {standard_task_runner.py:90} INFO - Running: ['***', 'tasks', 'run', 'dag_with_postgres_to_file_3', 'postgres_to_file', 'scheduled__2024-05-10T00:00:00+00:00', '--job-id', '147', '--raw', '--subdir', 'DAGS_FOLDER/postgres_to_csv.py', '--cfg-path', '/tmp/tmpsf_encxq']
[2024-05-13T03:54:13.808+0000] {standard_task_runner.py:91} INFO - Job 147: Subtask postgres_to_file
[2024-05-13T03:54:13.952+0000] {task_command.py:426} INFO - Running <TaskInstance: dag_with_postgres_to_file_3.postgres_to_file scheduled__2024-05-10T00:00:00+00:00 [running]> on host dab92a57e2e4
[2024-05-13T03:54:14.400+0000] {taskinstance.py:2648} INFO - Exporting env vars: AIRFLOW_CTX_DAG_OWNER='myself' AIRFLOW_CTX_DAG_ID='dag_with_postgres_to_file_3' AIRFLOW_CTX_TASK_ID='postgres_to_file' AIRFLOW_CTX_EXECUTION_DATE='2024-05-10T00:00:00+00:00' AIRFLOW_CTX_TRY_NUMBER='1' AIRFLOW_CTX_DAG_RUN_ID='scheduled__2024-05-10T00:00:00+00:00'
[2024-05-13T03:54:14.401+0000] {taskinstance.py:430} INFO - ::endgroup::
[2024-05-13T03:54:14.523+0000] {base.py:84} INFO - Using connection ID 'postgres_localhost' for task execution.
[2024-05-13T03:54:14.525+0000] {taskinstance.py:441} INFO - ::group::Post task execution logs
[2024-05-13T03:54:14.526+0000] {taskinstance.py:2905} ERROR - Task failed with exception
Traceback (most recent call last):
  File "/home/airflow/.local/lib/python3.12/site-packages/airflow/models/taskinstance.py", line 465, in _execute_task
    result = _execute_callable(context=context, **execute_callable_kwargs)
             ^^^^^^^^^^^^^^^^^^^^^^^^^^^^^^^^^^^^^^^^^^^^^^^^^^^^^^^^^^^^^
  File "/home/airflow/.local/lib/python3.12/site-packages/airflow/models/taskinstance.py", line 432, in _execute_callable
    return execute_callable(context=context, **execute_callable_kwargs)
           ^^^^^^^^^^^^^^^^^^^^^^^^^^^^^^^^^^^^^^^^^^^^^^^^^^^^^^^^^^^^
  File "/home/airflow/.local/lib/python3.12/site-packages/airflow/models/baseoperator.py", line 400, in wrapper
    return func(self, *args, **kwargs)
           ^^^^^^^^^^^^^^^^^^^^^^^^^^^
  File "/home/airflow/.local/lib/python3.12/site-packages/airflow/operators/python.py", line 235, in execute
    return_value = self.execute_callable()
                   ^^^^^^^^^^^^^^^^^^^^^^^
  File "/home/airflow/.local/lib/python3.12/site-packages/airflow/operators/python.py", line 252, in execute_callable
    return self.python_callable(*self.op_args, **self.op_kwargs)
           ^^^^^^^^^^^^^^^^^^^^^^^^^^^^^^^^^^^^^^^^^^^^^^^^^^^^^
  File "/opt/airflow/dags/postgres_to_csv.py", line 19, in postgres_to_file
    conn = hook.get_conn()
           ^^^^^^^^^^^^^^^
  File "/home/airflow/.local/lib/python3.12/site-packages/airflow/providers/postgres/hooks/postgres.py", line 161, in get_conn
    self.conn = psycopg2.connect(**conn_args)
                ^^^^^^^^^^^^^^^^^^^^^^^^^^^^^
  File "/home/airflow/.local/lib/python3.12/site-packages/psycopg2/__init__.py", line 122, in connect
    conn = _connect(dsn, connection_factory=connection_factory, **kwasync)
           ^^^^^^^^^^^^^^^^^^^^^^^^^^^^^^^^^^^^^^^^^^^^^^^^^^^^^^^^^^^^^^^
psycopg2.OperationalError: connection to server at "172.23.0.2", port 5432 failed: Connection refused
	Is the server running on that host and accepting TCP/IP connections?

[2024-05-13T03:54:14.569+0000] {taskinstance.py:1206} INFO - Marking task as UP_FOR_RETRY. dag_id=dag_with_postgres_to_file_3, task_id=postgres_to_file, run_id=scheduled__2024-05-10T00:00:00+00:00, execution_date=20240510T000000, start_date=20240513T035413, end_date=20240513T035414
[2024-05-13T03:54:14.636+0000] {standard_task_runner.py:110} ERROR - Failed to execute job 147 for task postgres_to_file (connection to server at "172.23.0.2", port 5432 failed: Connection refused
	Is the server running on that host and accepting TCP/IP connections?
; 272)
[2024-05-13T03:54:14.667+0000] {local_task_job_runner.py:240} INFO - Task exited with return code 1
[2024-05-13T03:54:14.776+0000] {taskinstance.py:3498} INFO - 0 downstream tasks scheduled from follow-on schedule check
[2024-05-13T03:54:14.781+0000] {local_task_job_runner.py:222} INFO - ::endgroup::
[2024-05-13T04:02:29.383+0000] {local_task_job_runner.py:120} INFO - ::group::Pre task execution logs
[2024-05-13T04:02:29.428+0000] {taskinstance.py:2076} INFO - Dependencies all met for dep_context=non-requeueable deps ti=<TaskInstance: dag_with_postgres_to_file_3.postgres_to_file scheduled__2024-05-10T00:00:00+00:00 [queued]>
[2024-05-13T04:02:29.440+0000] {taskinstance.py:2076} INFO - Dependencies all met for dep_context=requeueable deps ti=<TaskInstance: dag_with_postgres_to_file_3.postgres_to_file scheduled__2024-05-10T00:00:00+00:00 [queued]>
[2024-05-13T04:02:29.440+0000] {taskinstance.py:2306} INFO - Starting attempt 1 of 6
[2024-05-13T04:02:29.456+0000] {taskinstance.py:2330} INFO - Executing <Task(PythonOperator): postgres_to_file> on 2024-05-10 00:00:00+00:00
[2024-05-13T04:02:29.464+0000] {standard_task_runner.py:90} INFO - Running: ['***', 'tasks', 'run', 'dag_with_postgres_to_file_3', 'postgres_to_file', 'scheduled__2024-05-10T00:00:00+00:00', '--job-id', '175', '--raw', '--subdir', 'DAGS_FOLDER/postgres_to_csv.py', '--cfg-path', '/tmp/tmpc201_60y']
[2024-05-13T04:02:29.467+0000] {standard_task_runner.py:91} INFO - Job 175: Subtask postgres_to_file
[2024-05-13T04:02:29.468+0000] {logging_mixin.py:188} WARNING - /home/***/.local/lib/python3.12/site-packages/***/task/task_runner/standard_task_runner.py:61 DeprecationWarning: This process (pid=418) is multi-threaded, use of fork() may lead to deadlocks in the child.
[2024-05-13T04:02:29.469+0000] {standard_task_runner.py:63} INFO - Started process 421 to run task
[2024-05-13T04:02:29.528+0000] {task_command.py:426} INFO - Running <TaskInstance: dag_with_postgres_to_file_3.postgres_to_file scheduled__2024-05-10T00:00:00+00:00 [running]> on host dab92a57e2e4
[2024-05-13T04:02:29.667+0000] {taskinstance.py:2648} INFO - Exporting env vars: AIRFLOW_CTX_DAG_OWNER='myself' AIRFLOW_CTX_DAG_ID='dag_with_postgres_to_file_3' AIRFLOW_CTX_TASK_ID='postgres_to_file' AIRFLOW_CTX_EXECUTION_DATE='2024-05-10T00:00:00+00:00' AIRFLOW_CTX_TRY_NUMBER='1' AIRFLOW_CTX_DAG_RUN_ID='scheduled__2024-05-10T00:00:00+00:00'
[2024-05-13T04:02:29.668+0000] {taskinstance.py:430} INFO - ::endgroup::
[2024-05-13T04:02:29.701+0000] {base.py:84} INFO - Using connection ID 'postgres_localhost' for task execution.
[2024-05-13T04:02:29.711+0000] {postgres_to_csv.py:27} INFO - Saved orders data in text file
[2024-05-13T04:02:29.712+0000] {python.py:237} INFO - Done. Returned value was: None
[2024-05-13T04:02:29.712+0000] {taskinstance.py:441} INFO - ::group::Post task execution logs
[2024-05-13T04:02:29.724+0000] {taskinstance.py:1206} INFO - Marking task as SUCCESS. dag_id=dag_with_postgres_to_file_3, task_id=postgres_to_file, run_id=scheduled__2024-05-10T00:00:00+00:00, execution_date=20240510T000000, start_date=20240513T040229, end_date=20240513T040229
[2024-05-13T04:02:29.763+0000] {local_task_job_runner.py:240} INFO - Task exited with return code 0
[2024-05-13T04:02:29.791+0000] {taskinstance.py:3498} INFO - 0 downstream tasks scheduled from follow-on schedule check
[2024-05-13T04:02:29.793+0000] {local_task_job_runner.py:222} INFO - ::endgroup::
